# Translations template for nova.
# Copyright (C) 2014 ORGANIZATION
# This file is distributed under the same license as the nova project.
#
# Translators:
# Jorge Guerrero <lavidadigital@gmail.com>, 2014
msgid ""
msgstr ""
"Project-Id-Version: nova\n"
"Report-Msgid-Bugs-To: EMAIL@ADDRESS\n"
"POT-Creation-Date: 2014-12-04 06:15+0000\n"
"PO-Revision-Date: 2014-12-04 04:01+0000\n"
"Last-Translator: openstackjenkins <jenkins@openstack.org>\n"
"Language-Team: Spanish (http://www.transifex.com/projects/p/nova/language/"
"es/)\n"
"Language: es\n"
"MIME-Version: 1.0\n"
"Content-Type: text/plain; charset=UTF-8\n"
"Content-Transfer-Encoding: 8bit\n"
"Generated-By: Babel 1.3\n"
"Plural-Forms: nplurals=2; plural=(n != 1);\n"

#: nova/context.py:91
#, python-format
msgid "Arguments dropped when creating context: %s"
msgstr "Argumentos descartados al crear contexto: %s"

#: nova/debugger.py:80
msgid ""
"WARNING: Using the remote debug option changes how Nova uses the eventlet "
"library to support async IO. This could result in failures that do not occur "
"under normal operation. Use at your own risk."
msgstr ""
"ADVERTENCIA: Usar la opción de depuración remota cambia la forma en que Nova "
"utiliza la librería Eventlet para soportar IO asíncrono. Esto puede resultar "
"en fallos que no ocurrirían durante una operación normal. Úsela bajo su "
"propio riesgo."

#: nova/service.py:286
msgid "Service killed that has no database entry"
msgstr "Se detuvo un servicio sin entrada en la base de datos"

#: nova/utils.py:147
#, python-format
msgid "Expected to receive %(exp)s bytes, but actually %(act)s"
msgstr "Se esperaba recibir %(exp)s bytes, se han recibido %(act)s"

#: nova/api/auth.py:73
msgid "ratelimit_v3 is removed from v3 api."
msgstr "ratelimit_v3 se ha removido de la api v3."

#: nova/api/auth.py:169
msgid "Sourcing roles from deprecated X-Role HTTP header"
msgstr "Proporcionando roles de cabecera HTTP de rol X en desuso"

#: nova/api/ec2/__init__.py:170
#, python-format
msgid ""
"Access key %(access_key)s has had %(failures)d failed authentications and "
"will be locked out for %(lock_mins)d minutes."
msgstr ""
"La clave de acceso %(access_key)s ha tenido %(failures)d autenticaciones "
"anómalas y estará bloqueada durante %(lock_mins)d minutos."

#: nova/api/ec2/cloud.py:1313
#: nova/api/openstack/compute/contrib/floating_ips.py:236
#: nova/api/openstack/compute/plugins/v3/floating_ips.py:211
#, python-format
msgid "multiple fixed_ips exist, using the first: %s"
msgstr "existen múltiples fixed_ips, utilizando la primera: %s"

#: nova/api/metadata/handler.py:114
msgid ""
"X-Instance-ID present in request headers. The 'service_metadata_proxy' "
"option must be enabled to process this header."
msgstr ""

#: nova/api/metadata/handler.py:189
#, python-format
msgid ""
"X-Instance-ID-Signature: %(signature)s does not match the expected value: "
"%(expected_signature)s for id: %(instance_id)s. Request From: "
"%(remote_address)s"
msgstr ""

#: nova/api/metadata/handler.py:217
#, python-format
msgid ""
"Tenant_id %(tenant_id)s does not match tenant_id of instance %(instance_id)s."
msgstr ""
"Tenant_id %(tenant_id)s no coincide con tenant_id de la instancia "
"%(instance_id)s."

#: nova/api/metadata/vendordata_json.py:47
#, python-format
msgid "%(logprefix)sfile does not exist"
msgstr ""

#: nova/api/metadata/vendordata_json.py:50
#, python-format
msgid "%(logprefix)unexpected IOError when reading"
msgstr ""

#: nova/api/metadata/vendordata_json.py:54
#, python-format
msgid "%(logprefix)sfailed to load json"
msgstr ""

#: nova/api/openstack/__init__.py:236 nova/api/openstack/__init__.py:438
#, python-format
msgid ""
"Extension %(ext_name)s: Cannot extend resource %(collection)s: No such "
"resource"
msgstr ""
"Ampliación %(ext_name)s: no se puede ampliar el recurso %(collection)s: no "
"existe dicho recurso."

#: nova/api/openstack/__init__.py:289
#: nova/api/openstack/compute/plugins/v3/servers.py:109
#, python-format
msgid "Not loading %s because it is in the blacklist"
msgstr "No se ha cargado %s porque está en la lista negra"

#: nova/api/openstack/__init__.py:294
#: nova/api/openstack/compute/plugins/v3/servers.py:114
#, python-format
msgid "Not loading %s because it is not in the whitelist"
msgstr "No se ha cargado %s porque no está en la lista blanca"

#: nova/api/openstack/__init__.py:314
#, python-format
msgid "Extensions in both blacklist and whitelist: %s"
msgstr "Extensiones en lista restrictiva y lista permisiva: %s"

#: nova/api/openstack/common.py:498
msgid "Rejecting snapshot request, snapshots currently disabled"
msgstr ""
"Rechazando solicitud de instantánea, instantáneas inhabilitadas actualmente"

#: nova/api/openstack/extensions.py:278
#, python-format
msgid "Failed to load extension %(ext_factory)s: %(exc)s"
msgstr "No se ha podido cargar la ampliación %(ext_factory)s: %(exc)s"

#: nova/api/openstack/compute/servers.py:82
msgid ""
"XML support has been deprecated and may be removed as early as the Juno "
"release."
msgstr ""
"El soporte XML está obsoleto y podrá ser removito tan pronto como la "
"liberación de Juno."

#: nova/api/openstack/compute/views/servers.py:198
msgid "Instance has had its instance_type removed from the DB"
msgstr ""
"En la instancia se ha eliminado el tipo de instancia de la base de datos"

#: nova/cells/manager.py:79
msgid ""
"The cells feature of Nova is considered experimental by the OpenStack "
"project because it receives much less testing than the rest of Nova. This "
"may change in the future, but current deployers should be aware that the use "
"of it in production right now may be risky."
msgstr ""
"La característica de celdas en Nova se considera experimental por el "
"proyecto OpenStack debido a que recibe muchas menos pruebas el resto de "
"Nova. Esto puede cambiar en el futuro, pero los desplegadores actuales deben "
"estar concientes que el uso en producción ahora puede ser riesgoso."

#: nova/cells/messaging.py:1213
#, python-format
msgid "No match when trying to update BDM: %(bdm)s"
msgstr "No se encontró resultado al intentar actualizar BDM: %(bdm)s"

#: nova/cells/messaging.py:1694
#, python-format
msgid "No cell_name for %(method)s() from API"
msgstr "No hay cell_name para %(method)s() desde la API"

#: nova/cells/messaging.py:1711
msgid "No cell_name for instance update from API"
msgstr "No hay cell_name para actualización de instancia desde la API"

#: nova/cells/weights/mute_child.py:66
#, python-format
msgid ""
"%(cell)s has not been seen since %(last_seen)s and is being treated as mute."
msgstr ""
"%(cell)s no se ha observador desde %(last_seen)s y se está tratando como en "
"estado apagado."

#: nova/compute/manager.py:947
#, python-format
msgid ""
"Instance in transitional state (%(task_state)s) at start-up and power state "
"is (%(power_state)s), clearing task state"
msgstr ""
"Instancia en estado transicional (%(task_state)s) al arranque y estado de "
"energía es (%(power_state)s), limpiando el estado de la tarea"

#: nova/compute/manager.py:958
#, python-format
msgid ""
"Instance in transitional state (%(task_state)s) at start-up and power state "
"is (%(power_state)s), clearing task state and unpausing the instance"
msgstr ""

#: nova/compute/manager.py:1260
#, python-format
msgid ""
"Treating negative config value (%(retries)s) for 'block_device_retries' as 0."
msgstr ""

#: nova/compute/manager.py:1859
msgid ""
"Failed to create block device for instance due to being over volume resource "
"quota"
msgstr ""
"No se pudo crear el dispositivo de bloque, debido a que se ha superado la "
"cuota establecida para el volumen."

#: nova/compute/manager.py:2156
msgid "No more network or fixed IP to be allocated"
msgstr ""

#: nova/compute/manager.py:2432
#, python-format
msgid "Ignoring EndpointNotFound: %s"
msgstr ""

#: nova/compute/manager.py:2450
#, python-format
msgid "Failed to delete volume: %(volume_id)s due to %(exc)s"
msgstr ""

#: nova/compute/manager.py:4619
#, python-format
msgid ""
"Ignoring DiskNotFound exception while detaching volume %(volume_id)s from "
"%(mp)s: %(err)s"
msgstr ""

#: nova/compute/manager.py:5851
#, python-format
msgid ""
"Instance shutdown by itself. Calling the stop API. Current vm_state: "
"%(vm_state)s, current task_state: %(task_state)s, current DB power_state: "
"%(db_power_state)s, current VM power_state: %(vm_power_state)s"
msgstr ""

#: nova/compute/manager.py:5906
#, python-format
msgid ""
"Instance is not stopped. Calling the stop API. Current vm_state: "
"%(vm_state)s, current task_state: %(task_state)s, current DB power_state: "
"%(db_power_state)s, current VM power_state: %(vm_power_state)s"
msgstr ""

#: nova/compute/utils.py:222
#, python-format
msgid "Can't access image %(image_id)s: %(error)s"
msgstr "No se puede acceder a la imagen %(image_id)s: %(error)s"

#: nova/compute/utils.py:252
#, python-format
msgid ""
"Metadata value %(value)s for %(key)s is not of type %(type)s. Using default "
"value %(default)s."
msgstr ""

#: nova/compute/utils.py:376
#, python-format
msgid ""
"No host name specified for the notification of HostAPI.%s and it will be "
"ignored"
msgstr ""
"No ha sido especificado un nombre de anfitrión para la notificación de "
"HostAPI.%s y será ignorada"

#: nova/compute/resources/__init__.py:31
#, python-format
msgid "Compute resource plugin %s was not loaded"
msgstr ""

#: nova/conductor/api.py:320
msgid ""
"Timed out waiting for nova-conductor.  Is it running? Or did this service "
"start before nova-conductor?  Reattempting establishment of nova-conductor "
"connection..."
msgstr ""

#: nova/conductor/manager.py:733
msgid "No valid host found for unshelve instance"
msgstr "No se ha encontrado anfitrión válido para extraer instancia"

#: nova/conductor/manager.py:776
msgid "No valid host found for rebuild"
msgstr ""

#: nova/console/serial.py:98
#, python-format
msgid ""
"serial_console.port_range should be <num>:<num>. Given value %(port_range)s "
"could not be parsed. Taking the default port range %(default)s."
msgstr ""

#: nova/consoleauth/manager.py:84
#, python-format
msgid "Token: %(token)s failed to save into memcached."
msgstr ""

#: nova/consoleauth/manager.py:95
#, python-format
msgid "Instance: %(instance_uuid)s failed to save into memcached"
msgstr ""

#: nova/db/sqlalchemy/api.py:185
#, python-format
msgid "Deadlock detected when running '%(func_name)s': Retrying..."
msgstr "Punto muerto detectado al ejecutar '%(func_name)s': Reintentando..."

#: nova/db/sqlalchemy/api.py:3487
#, python-format
msgid "Change will make usage less than 0 for the following resources: %s"
msgstr "El cambio hará el uso menos de 0 para los siguientes recursos: %s"

#: nova/keymgr/mock_key_mgr.py:54
msgid "This key manager is not suitable for use in production deployments"
msgstr ""
"Este administrador de claves no es adecuado para uso en liberaciones de "
"producción"

#: nova/keymgr/single_key_mgr.py:40
msgid ""
"This key manager is insecure and is not recommended for production "
"deployments"
msgstr ""
"Este administrador de claves es inseguro y no se recomienda para "
"liberaciones de producción."

#: nova/keymgr/single_key_mgr.py:72
#, python-format
msgid "Not deleting key %s"
msgstr "Sin eliminar la clave %s"

#: nova/network/floating_ips.py:195
#, python-format
msgid "Address |%(address)s| is not allocated"
msgstr "La dirección |%(address)s| no está asignada"

#: nova/network/floating_ips.py:199
#, python-format
msgid "Address |%(address)s| is not allocated to your project |%(project)s|"
msgstr "La dirección |%(address)s| no está asignada al proyecto |%(project)s|"

#: nova/network/floating_ips.py:219
#, python-format
msgid "Quota exceeded for %s, tried to allocate floating IP"
msgstr "Cuota excedida para %s, intentando asignar dirección IP flotante"

#: nova/network/floating_ips.py:376
#, python-format
msgid "Failed to disassociated floating address: %s"
msgstr "Fallo al desasociar la dirección IP flotante: %s"

#: nova/network/floating_ips.py:541
#, python-format
msgid ""
"Floating ip address |%(address)s| no longer belongs to instance "
"%(instance_uuid)s. Will not migrate it "
msgstr ""
"La dirección IP flotante | %(address)s | ya no pertentece a la instancia "
"%(instance_uuid)s. No será migrada"

#: nova/network/floating_ips.py:578
#, python-format
msgid ""
"Floating ip address |%(address)s| no longer belongs to instance "
"%(instance_uuid)s. Will not setup it."
msgstr ""

#: nova/network/floating_ips.py:622
#, python-format
msgid ""
"Database inconsistency: DNS domain |%s| is registered in the Nova db but not "
"visible to either the floating or instance DNS driver. It will be ignored."
msgstr ""
"Incoherencia de base de datos: el dominio DNS |%s| está registrado en la "
"base de datos Nova pero no es visible para el controlador DNS de instancia o "
"flotante. Se ignorará."

#: nova/network/floating_ips.py:662
#, python-format
msgid "Domain |%(domain)s| already exists, changing zone to |%(av_zone)s|."
msgstr "El dominio |%(domain)s| ya existe, cambiando zona a |%(av_zone)s|."

#: nova/network/floating_ips.py:671
#, python-format
msgid "Domain |%(domain)s| already exists, changing project to |%(project)s|."
msgstr ""
"El dominio |%(domain)s| ya existe, cambiando el proyecto a |%(project)s."

#: nova/network/ldapdns.py:108
#, python-format
msgid ""
"Found multiple matches for domain %(domain)s.\n"
"%(entry)s"
msgstr ""
"Se han encontrado varias coincidencias para el dominio %(domain)s.\n"
"%(entry)s"

#: nova/network/ldapdns.py:135
#, python-format
msgid "Unable to dequalify.  %(name)s is not in %(domain)s.\n"
msgstr "No se puede descalificar.  %(name)s no está en %(domain)s.\n"

#: nova/network/ldapdns.py:376
msgid "This shouldn't be getting called except during testing."
msgstr "Esto no se debe llamar excepto durante las pruebas. "

#: nova/network/linux_net.py:235
#, python-format
msgid "Attempted to remove chain %s which does not exist"
msgstr "Se ha intentado eliminar la cadena %s que no existe"

#: nova/network/linux_net.py:304
#, python-format
msgid ""
"Tried to remove rule that was not there: %(chain)r %(rule)r %(wrap)r %(top)r"
msgstr ""
"Se ha intentado eliminar una regla que no estaba allí: %(chain)r %(rule)r "
"%(wrap)r %(top)r"

#: nova/network/linux_net.py:1669
#, python-format
msgid "%s failed. Not Retrying."
msgstr ""

#: nova/network/linux_net.py:1672
#, python-format
msgid "%s failed. Retrying."
msgstr ""

#: nova/network/manager.py:808
#, python-format
msgid "instance-dns-zone not found |%s|."
msgstr "instance-dns-zone no encontrada |%s|"

#: nova/network/manager.py:815
#, python-format
msgid ""
"instance-dns-zone is |%(domain)s|, which is in availability zone |%(zone)s|. "
"Instance is in zone |%(zone2)s|. No DNS record will be created."
msgstr ""
"instance-dns-zone es |%(domain)s|, que está en la zona de disponibilidad |"
"%(zone)s|. La instancia está en la zona |%(zone2)s|. No se creará ningún "
"registro de DNS."

#: nova/network/manager.py:858
#, python-format
msgid ""
"Quota exceeded for project %(pid)s, tried to allocate fixed IP. %(used)s of "
"%(allowed)s are in use or are already reserved."
msgstr ""

#: nova/network/manager.py:953
msgid "Error cleaning up fixed ip allocation. Manual cleanup may be required."
msgstr ""

#: nova/network/manager.py:1055
#, python-format
msgid "Failed to rollback quota for deallocate fixed ip: %s"
msgstr ""

#: nova/network/manager.py:1068
#, python-format
msgid "IP %s leased that is not associated"
msgstr "La IP %s alquilada que no está asociada "

#: nova/network/manager.py:1074
#, python-format
msgid "IP |%s| leased that isn't allocated"
msgstr "IP |%s| alquilada que no está asignada"

#: nova/network/manager.py:1083
#, python-format
msgid "IP %s released that is not associated"
msgstr "IP %s liberada que no está asociada"

#: nova/network/manager.py:1087
#, python-format
msgid "IP %s released that was not leased"
msgstr "IP %s liberada que no está alquilada"

#: nova/network/minidns.py:122
#, python-format
msgid "Cannot delete entry |%s|"
msgstr "No se puede suprimir la entrada |%s|"

#: nova/network/minidns.py:207
#, python-format
msgid "Cannot delete domain |%s|"
msgstr "No se puede suprimir el dominio |%s|"

#: nova/network/neutronv2/api.py:187
#, python-format
msgid "Neutron error: Fixed IP %s is already in use."
msgstr ""

#: nova/network/neutronv2/api.py:192
#, python-format
msgid "Neutron error: Port quota exceeded in tenant: %s"
msgstr ""

#: nova/network/neutronv2/api.py:197
#, python-format
msgid "Neutron error: No more fixed IPs in network: %s"
msgstr ""

#: nova/network/neutronv2/api.py:201
#, python-format
msgid ""
"Neutron error: MAC address %(mac)s is already in use on network %(network)s."
msgstr ""

#: nova/network/neutronv2/api.py:301
msgid "No network configured!"
msgstr "No hay red configurada!"

#: nova/network/neutronv2/api.py:501
#, python-format
msgid "Port %s does not exist"
msgstr "El puerto %s no existe"

#: nova/network/neutronv2/api.py:505
#, python-format
msgid "Failed to delete port %s for instance."
msgstr ""

#: nova/network/neutronv2/api.py:1275
#, python-format
msgid ""
"Network %(id)s not matched with the tenants network! The ports tenant "
"%(tenant_id)s will be used."
msgstr ""
"La red %(id)s no coincide con las redes de los inquilinos! El puerto del "
"inquilino %(tenant_id)s será utilizado."

#: nova/network/security_group/neutron_driver.py:431
#, python-format
msgid ""
"Cannot add security group %(name)s to %(instance)s since the port "
"%(port_id)s does not meet security requirements"
msgstr ""
"No se puede añadir el grupo de seguridad %(name)s a %(instance)s ya que el "
"puerto %(port_id)s no cumple los requisitos de seguridad"

#: nova/openstack/common/loopingcall.py:87
#, python-format
msgid "task %(func_name)s run outlasted interval by %(delay).2f sec"
msgstr ""

#: nova/openstack/common/policy.py:254
#, python-format
msgid "Can not find policy directory: %s"
msgstr ""

#: nova/openstack/common/service.py:356
#, python-format
msgid "pid %d not in child list"
msgstr "El pid %d no está en la lista de hijos"

#: nova/pci/manager.py:112
#, python-format
msgid ""
"Trying to remove device with %(status)s ownership %(instance_uuid)s because "
"of %(pci_exception)s"
msgstr ""
"Intentando remover dispositivo con %(status)s con propiedad "
"%(instance_uuid)s debido a %(pci_exception)s"

#: nova/scheduler/driver.py:56
#, python-format
msgid "NoValidHost exception with message: '%s'"
msgstr ""

#: nova/scheduler/driver.py:62 nova/scheduler/utils.py:93
#, python-format
msgid "Setting instance to %s state."
msgstr "Estableciendo instancia hacia estado %s"

#: nova/scheduler/filter_scheduler.py:182
msgid "Instance disappeared during scheduling"
msgstr "La instancia ha desaparecido durante la programación"

#: nova/scheduler/host_manager.py:170
#, python-format
msgid "Metric name unknown of %r"
msgstr "Nombre de métrica desconocido para %r"

#: nova/scheduler/host_manager.py:185
#: nova/tests/unit/scheduler/test_host_manager.py:285
#, python-format
msgid ""
"Host %(hostname)s has more disk space than database expected (%(physical)sgb "
"> %(database)sgb)"
msgstr ""

#: nova/scheduler/host_manager.py:404
#: nova/tests/unit/scheduler/test_host_manager.py:291
#, python-format
msgid "No service for compute ID %s"
msgstr "No hay servicio para el ID de cálculo %s "

#: nova/scheduler/utils.py:77
#, python-format
msgid "Failed to %(service)s_%(method)s: %(ex)s"
msgstr "Fallo para %(service)s_%(method)s: %(ex)s"

#: nova/scheduler/utils.py:233
#, python-format
msgid "Ignoring the invalid elements of the option %(name)s: %(options)s"
msgstr "Ignorando los elementos inválidos de la opción %(name)s: %(options)s"

#: nova/scheduler/filters/compute_filter.py:47
#, python-format
msgid "%(host_state)s has not been heard from in a while"
msgstr "%(host_state)s no ha sido recibido durante un tiempo"

#: nova/scheduler/filters/core_filter.py:51
#: nova/scheduler/filters/exact_core_filter.py:36
msgid "VCPUs not set; assuming CPU collection broken"
msgstr ""
"VCPU no establecidas; suponiendo que la colección de CPU se ha interrumpido"

#: nova/scheduler/filters/core_filter.py:102
#, python-format
msgid "Could not decode cpu_allocation_ratio: '%s'"
msgstr "No se puede decodificar cpu_allocation_ratio: '%s'"

#: nova/scheduler/filters/disk_filter.py:87
#, python-format
msgid "Could not decode disk_allocation_ratio: '%s'"
msgstr ""

#: nova/scheduler/filters/io_ops_filter.py:76
#, python-format
msgid "Could not decode max_io_ops_per_host: '%s'"
msgstr ""

#: nova/scheduler/filters/num_instances_filter.py:71
#, python-format
msgid "Could not decode max_instances_per_host: '%s'"
msgstr ""

#: nova/scheduler/filters/ram_filter.py:95
#, python-format
msgid "Could not decode ram_allocation_ratio: '%s'"
msgstr "No se puede decodificar ram_allocation_ratio: '%s'"

#: nova/servicegroup/api.py:88
#, python-format
msgid ""
"Report interval must be less than service down time. Current config: "
"<service_down_time: %(service_down_time)s, report_interval: "
"%(report_interval)s>. Setting service_down_time to: %(new_service_down_time)s"
msgstr ""
"El intérvalo de reporte debe ser menor que el tiempo fuera de servicio. "
"Configuración actual: <service_down_time: %(service_down_time)s, "
"report_interval: %(report_interval)s>. Configuración service_down_time a: "
"%(new_service_down_time)s"

#: nova/storage/linuxscsi.py:101
#, python-format
msgid "Multipath call failed exit (%(code)s)"
msgstr "La llamada a multivía de acceso no ha podido salir (%(code)s)"

#: nova/storage/linuxscsi.py:122
#, python-format
msgid "Couldn't find multipath device %s"
msgstr "No se puede encontrar el dispositivo multiruta %s"

#: nova/storage/linuxscsi.py:131
#, python-format
msgid "Skip faulty line \"%(dev_line)s\" of multipath device %(mdev)s"
msgstr ""

#: nova/virt/configdrive.py:178
#, python-format
msgid "Image config drive option %(image_prop)s is invalid and will be ignored"
msgstr ""

#: nova/virt/disk/api.py:366
#, python-format
msgid "Ignoring error injecting data into image %(image)s (%(e)s)"
msgstr ""

#: nova/virt/disk/api.py:456
#, python-format
msgid "Ignoring error injecting %(inject)s into image (%(e)s)"
msgstr "Ignorando el error al inyectar %(inject)s en la imagen (%(e)s)"

#: nova/virt/disk/vfs/guestfs.py:88
msgid ""
"Please consider to execute setup before trying to configure debug log "
"message."
msgstr ""

#: nova/virt/disk/vfs/guestfs.py:192
#, python-format
msgid "Unable to force TCG mode, libguestfs too old? %s"
msgstr ""

#: nova/virt/hyperv/vmops.py:458
msgid "Timed out while waiting for soft shutdown."
msgstr ""

#: nova/virt/hyperv/vmutils.py:444
#, python-format
msgid ""
"Disk not found on controller \"%(controller_path)s\" with address "
"\"%(address)s\""
msgstr ""

#: nova/virt/ironic/driver.py:104
#, python-format
msgid "Power state %s not found."
msgstr ""

#: nova/virt/ironic/driver.py:205
#, python-format
msgid "cpu_arch not defined for node '%s'"
msgstr ""

#: nova/virt/ironic/driver.py:233
#, python-format
msgid "Ignoring malformed capability '%s'. Format should be 'key:val'."
msgstr ""

#: nova/virt/ironic/driver.py:531
#, python-format
msgid "Warning, memory usage is 0 for %(instance)s on baremetal node %(node)s."
msgstr ""

#: nova/virt/ironic/driver.py:538
#, python-format
msgid ""
"Warning, number of cpus is 0 for %(instance)s on baremetal node %(node)s."
msgstr ""

#: nova/virt/ironic/driver.py:726
#, python-format
msgid "Destroy called on non-existing instance %s."
msgstr ""

#: nova/virt/libvirt/driver.py:416
#, python-format
msgid "Invalid cachemode %(cache_mode)s specified for disk type %(disk_type)s."
msgstr ""
"Modalidad de caché %(cache_mode)s no válida especificada para el tipo de "
"disco %(disk_type)s."

#: nova/virt/libvirt/driver.py:490
#, python-format
msgid ""
"The libvirt driver is not tested on %(type)s/%(arch)s by the OpenStack "
"project and thus its quality can not be ensured. For more information, see: "
"https://wiki.openstack.org/wiki/HypervisorSupportMatrix"
msgstr ""
"El controlador libvirt no ha sido probado en %(type)s/%(arch)s por el "
"projecto de OpenStack  por lo cual su calidad no puede ser asegurada. Para "
"mas información, ver: https://wiki.openstack.org/wiki/HypervisorSupportMatrix"

#: nova/virt/libvirt/driver.py:511
msgid ""
"Running libvirt-lxc without user namespaces is dangerous. Containers spawned "
"by Nova will be run as the host's root user. It is highly suggested that "
"user namespaces be used in a public or multi-tenant environment."
msgstr ""

#: nova/virt/libvirt/driver.py:706
msgid "Cannot destroy instance, operation time out"
msgstr ""
"No se puede destruir intsancia, tiempo de espera agotado para la operación"

#: nova/virt/libvirt/driver.py:730
msgid "During wait destroy, instance disappeared."
msgstr "Durante la destrucción de espera, la instancia ha desaparecido."

#: nova/virt/libvirt/driver.py:817
msgid "Instance may be still running, destroy it again."
msgstr "Puede que la instancia aún se esté ejecutando, vuelva a destruirla."

#: nova/virt/libvirt/driver.py:872
#, python-format
msgid "Ignoring Volume Error on vol %(vol_id)s during delete %(exc)s"
msgstr ""
"Ignorando Error de volumen en volumen %(vol_id)s durante la remocion %(exc)s"

#: nova/virt/libvirt/driver.py:1229 nova/virt/libvirt/driver.py:1237
msgid "During detach_volume, instance disappeared."
msgstr "Durante detach_volume, la instancia ha desaparecido."

#: nova/virt/libvirt/driver.py:1282
msgid "During detach_interface, instance disappeared."
msgstr "Durante detach_interface, la instancia ha desaparecido."

#: nova/virt/libvirt/driver.py:1958
msgid "Failed to soft reboot instance. Trying hard reboot."
msgstr ""
"Fallo al reiniciar la instancia de manera suave. Intentando reinicio duro."

#: nova/virt/libvirt/driver.py:2600
#, python-format
msgid "Image %s not found on disk storage. Continue without injecting data"
msgstr ""
"La imagen %s no se ha encontrado en el almacenamiento de disco. Continuando "
"sin inyectar datos."

#: nova/virt/libvirt/driver.py:2786
msgid "File injection into a boot from volume instance is not supported"
msgstr ""
"La inyección de archivo al arranque desde la instancia del volumen no está "
"soportado."

#: nova/virt/libvirt/driver.py:2861
msgid "Instance disappeared while detaching a PCI device from it."
msgstr ""
"La instancia ha desaparecido mientras se removía el dispositivo PCI de ella."

#: nova/virt/libvirt/driver.py:2981
#, python-format
msgid "Cannot update service status on host: %s,since it is not registered."
msgstr ""
"No se puede actualizar el estado del servicio en el anfitrión: %s, ya que el "
"mismo no está registrado."

#: nova/virt/libvirt/driver.py:2984
#, python-format
msgid ""
"Cannot update service status on host: %s,due to an unexpected exception."
msgstr ""
"No se puede atualizar el estado del servicio en el anfitrión: %s, debido a "
"una excepción inesperada."

#: nova/virt/libvirt/driver.py:3012
#, python-format
msgid "URI %(uri)s does not support full set of host capabilities: %(error)s"
msgstr ""

#: nova/virt/libvirt/driver.py:3324
msgid "Too many id maps, only included first five."
msgstr ""

#: nova/virt/libvirt/driver.py:3334
#, python-format
msgid "Invalid value for id mapping %s"
msgstr ""

#: nova/virt/libvirt/driver.py:3844
msgid ""
"Old property name \"hw_watchdog_action\" is now deprecated and will be "
"removed in the next release. Use updated property name \"hw:watchdog_action"
"\" instead"
msgstr ""

#: nova/virt/libvirt/driver.py:4175
#, python-format
msgid "Timeout waiting for vif plugging callback for instance %(uuid)s"
msgstr ""
"Tiempo excedido para la llamada inversa de la conexión vif para la instancia "
"%(uuid)s"

#: nova/virt/libvirt/driver.py:4196
#, python-format
msgid "couldn't obtain the XML from domain: %(uuid)s, exception: %(ex)s"
msgstr ""

#: nova/virt/libvirt/driver.py:4253
msgid ""
"Cannot get the number of cpu, because this function is not implemented for "
"this platform. "
msgstr ""
"No se puede obtener el número de CPU porque esta función no está "
"implementada para esta plataforma. "

#: nova/virt/libvirt/driver.py:4315
#, python-format
msgid ""
"couldn't obtain the vpu count from domain id: %(uuid)s, exception: %(ex)s"
msgstr ""

#: nova/virt/libvirt/driver.py:4346
#, python-format
msgid "couldn't obtain the memory from domain: %(uuid)s, exception: %(ex)s"
msgstr ""

#: nova/virt/libvirt/driver.py:4551
#, python-format
msgid "URI %(uri)s does not support listDevices: %(error)s"
msgstr ""

#: nova/virt/libvirt/driver.py:5183
#, python-format
msgid ""
"An error occurred trying to live migrate. Falling back to legacy live "
"migrate flow. Error: %s"
msgstr ""

#: nova/virt/libvirt/driver.py:5321
#, python-format
msgid "plug_vifs() failed %(cnt)d. Retry up to %(max_retry)d."
msgstr "plug_vifs() ha fallado %(cnt)d. Intentando hasta %(max_retry)d."

#: nova/virt/libvirt/driver.py:5534
#, python-format
msgid ""
"Error from libvirt while getting description of %(instance_name)s: [Error "
"Code %(error_code)s] %(ex)s"
msgstr ""
"Error de libvirt al obtener la descripción de %(instance_name)s: [Código de "
"error %(error_code)s] %(ex)s"

#: nova/virt/libvirt/driver.py:5542
#, python-format
msgid ""
"Periodic task is updating the host stat, it is trying to get disk "
"%(i_name)s, but disk file was removed by concurrent operations such as "
"resize."
msgstr ""
"La tarea periódica está actualizando las estadísticas del anfitrión, está "
"intentando obtener el disco %(i_name)s, pero el disco ha sido removido por "
"operaciones concurrentes como la modificación de tamaño."

#: nova/virt/libvirt/driver.py:5548
#, python-format
msgid ""
"Periodic task is updating the host stat, it is trying to get disk "
"%(i_name)s, but access is denied. It is most likely due to a VM that exists "
"on the compute node but is not managed by Nova."
msgstr ""

#: nova/virt/libvirt/driver.py:5557
#, python-format
msgid ""
"Periodic task is updating the host stats, it is trying to get disk info for "
"%(i_name)s, but the backing volume block device was removed by concurrent "
"operations such as resize. Error: %(error)s"
msgstr ""

#: nova/virt/libvirt/firewall.py:53
msgid ""
"Libvirt module could not be loaded. NWFilterFirewall will not work correctly."
msgstr ""
"El módulo lLibvirt no se ha podido cargar. NWFilterFirewall no funcionará "
"correctamente."

#: nova/virt/libvirt/host.py:368
#, python-format
msgid "URI %(uri)s does not support events: %(error)s"
msgstr "URI %(uri)s no soporta eventos: %(error)s"

#: nova/virt/libvirt/host.py:384
#, python-format
msgid "URI %(uri)s does not support connection events: %(error)s"
msgstr "URI %(uri)s no soporta eventos de conexión: %(error)s"

#: nova/virt/libvirt/imagecache.py:330
#, python-format
msgid ""
"Instance %(instance)s is using a backing file %(backing)s which does not "
"appear in the image service"
msgstr ""
"La instancia %(instance)s utiliza un archivo de respaldo %(backing)s que no "
"aparece en el servicio de la imagen"

#: nova/virt/libvirt/imagecache.py:522
#, python-format
msgid ""
"image %(id)s at (%(base_file)s): warning -- an absent base file is in use! "
"instances: %(instance_list)s"
msgstr ""
"%(id)s (%(base_file)s): aviso -- se está utilizando un archivo base ausente. "
"instancias: %(instance_list)s"

#: nova/virt/libvirt/imagecache.py:562
#, python-format
msgid "%s swap image was used by instance but no back files existing!"
msgstr ""

#: nova/virt/libvirt/imagecache.py:588
#, python-format
msgid "Unknown base file: %s"
msgstr "Archivo de base desconocido: %s "

#: nova/virt/libvirt/lvm.py:104
#, python-format
msgid ""
"Volume group %(vg)s will not be able to hold sparse volume %(lv)s. Virtual "
"volume size is %(size)db, but free space on volume group is only "
"%(free_space)db."
msgstr ""
"El grupo de volumen %(vg)s no podrá retener el volumen disperso %(lv)s. El "
"tamaño del volumen virtual es %(size)db, pero el espacio libre en el grupo "
"de volúmenes es solo %(free_space)db."

#: nova/virt/libvirt/rbd_utils.py:269
#, python-format
msgid "rbd remove %(volume)s in pool %(pool)s failed"
msgstr ""

#: nova/virt/libvirt/utils.py:71 nova/virt/libvirt/utils.py:77
msgid "systool is not installed"
msgstr "systool no está instalado"

#: nova/virt/libvirt/volume.py:133
#, python-format
msgid "Unknown content in connection_info/qos_specs: %s"
msgstr "Contenido desconocido en connection_info/qos_specs: %s"

#: nova/virt/libvirt/volume.py:332
#, python-format
msgid ""
"ISCSI volume not yet found at: %(disk_dev)s. Will rescan & retry.  Try "
"number: %(tries)s"
msgstr ""
"El volumen ISCSI aún no se ha encontrado en: %(disk_dev)s. Se volverá a "
"explorar y se reintentará. Número de intentos: %(tries)s"

#: nova/virt/libvirt/volume.py:403
#, python-format
msgid "Unable to delete volume device %s"
msgstr "Incapaz de eliminar el dispositivo de volumen %s"

#: nova/virt/libvirt/volume.py:414
#, python-format
msgid ""
"Failed to remove multipath device descriptor %(dev_mapper)s. Exception "
"message: %(msg)s"
msgstr ""
"Fallo al remover el descriptor del dispositivo multiruta %(dev_mapper)s. "
"Mensaje de excepción: %(msg)s"

#: nova/virt/libvirt/volume.py:748 nova/virt/libvirt/volume.py:922
#, python-format
msgid "%s is already mounted"
msgstr "%s ya está montado "

#: nova/virt/libvirt/volume.py:809
#, python-format
msgid "AoE volume not yet found at: %(aoedevpath)s. Try number: %(tries)s"
msgstr ""
"El volumen AoE aún no se ha encontrado en: %(aoedevpath)s. Número de "
"intentos: %(tries)s"

#: nova/virt/libvirt/volume.py:1019
#, python-format
msgid ""
"Fibre volume not yet found at: %(mount_device)s. Will rescan & retry.  Try "
"number: %(tries)s"
msgstr ""
"El volumen de fibra aún no se ha encontrado en: %(mount_device)s. Se volverá "
"a explorar y se reintentará. Número de intentos: %(tries)s"

#: nova/virt/libvirt/volume.py:1075
#, python-format
msgid "multipath-tools probably work improperly. devices to remove = %s."
msgstr ""

#: nova/virt/libvirt/volume.py:1129
msgid "Value required for 'scality_sofs_config'"
msgstr "Valor necesario para 'scality_sofs_config'"

#: nova/virt/libvirt/volume.py:1140
#, python-format
msgid "Cannot access 'scality_sofs_config': %s"
msgstr "No se puede acceder a 'scality_sofs_config': %s"

#: nova/virt/libvirt/volume.py:1146
msgid "Cannot execute /sbin/mount.sofs"
msgstr "No se puede ejecutar /sbin/mount.sofs"

#: nova/virt/libvirt/volume.py:1161
msgid "Cannot mount Scality SOFS, check syslog for errors"
msgstr "No se puede montar Scality SOFS, compruebe syslog por si hay errores"

#: nova/virt/vmwareapi/driver.py:163
#, python-format
msgid "The following clusters could not be found in the vCenter %s"
msgstr "Los siguientes clusters no pueden ser encontrados en el vcenter %s"

#: nova/virt/vmwareapi/driver.py:210
msgid "datastore_regex is ignored when PBM is enabled"
msgstr ""

#: nova/virt/vmwareapi/driver.py:255
msgid "Instance cannot be found in host, or in an unknownstate."
msgstr ""
"La instancia no se puede encontrar en el anfitrión o en un estado desconocido"

#: nova/virt/vmwareapi/vm_util.py:1225
#, python-format
msgid ""
"vmware_ostype from image is not recognised: '%(ostype)s'. An invalid os type "
"may be one cause of this instance creation failure"
msgstr ""

#: nova/virt/vmwareapi/vmops.py:374
#, python-format
msgid ""
"Destination %s already exists! Concurrent moves can lead to unexpected "
"results."
msgstr ""

#: nova/volume/cinder.py:122
msgid ""
"Cinder V1 API is deprecated as of the Juno release, and Nova is still "
"configured to use it. Enable the V2 API in Cinder and set "
"cinder_catalog_info in nova.conf to use it."
msgstr ""
