# Translations template for nova.
# Copyright (C) 2014 ORGANIZATION
# This file is distributed under the same license as the nova project.
#
# Translators:
# Frédéric <frosmont@free.fr>, 2014
# Maxime COQUEREL <max.coquerel@gmail.com>, 2014
msgid ""
msgstr ""
"Project-Id-Version: nova\n"
"Report-Msgid-Bugs-To: EMAIL@ADDRESS\n"
"POT-Creation-Date: 2014-12-02 06:15+0000\n"
"PO-Revision-Date: 2014-12-02 04:01+0000\n"
"Last-Translator: openstackjenkins <jenkins@openstack.org>\n"
"Language-Team: French (http://www.transifex.com/projects/p/nova/language/"
"fr/)\n"
"Language: fr\n"
"MIME-Version: 1.0\n"
"Content-Type: text/plain; charset=UTF-8\n"
"Content-Transfer-Encoding: 8bit\n"
"Generated-By: Babel 1.3\n"
"Plural-Forms: nplurals=2; plural=(n > 1);\n"

#: nova/context.py:91
#, python-format
msgid "Arguments dropped when creating context: %s"
msgstr "Arguments supprimés lors de la création du contexte : %s"

#: nova/debugger.py:80
msgid ""
"WARNING: Using the remote debug option changes how Nova uses the eventlet "
"library to support async IO. This could result in failures that do not occur "
"under normal operation. Use at your own risk."
msgstr ""
"AVERTISSEMENT : Utiliser l'option de debug à distance change la façon dont "
"Nova utilise la librairie eventlet pour supporter IO asynchrone. Cela "
"pourrait entraîner des défaillances qui ne se produisent pas en "
"fonctionnement normal. A utiliser à vos risques et périls."

#: nova/service.py:286
msgid "Service killed that has no database entry"
msgstr "Service détruit sans entrée dans la base de données"

#: nova/utils.py:147
#, python-format
msgid "Expected to receive %(exp)s bytes, but actually %(act)s"
msgstr "En attente de %(exp)s octets, reçu uniquement %(act)s"

#: nova/api/auth.py:73
msgid "ratelimit_v3 is removed from v3 api."
msgstr "ratelimit_v3 est supprimé de l'api v3."

#: nova/api/auth.py:169
msgid "Sourcing roles from deprecated X-Role HTTP header"
msgstr "Sourçage des rôles à partir de l'en-tête HTTP X-Role obsolète"

#: nova/api/ec2/__init__.py:170
#, python-format
msgid ""
"Access key %(access_key)s has had %(failures)d failed authentications and "
"will be locked out for %(lock_mins)d minutes."
msgstr ""
"La clef d'accès %(access_key)s a rencontrée %(failures)d echecs "
"d'authentification et sera par conséquent vérouillée pour %(lock_mins)d "
"minutes."

#: nova/api/ec2/cloud.py:1312
#: nova/api/openstack/compute/contrib/floating_ips.py:236
#: nova/api/openstack/compute/plugins/v3/floating_ips.py:211
#, python-format
msgid "multiple fixed_ips exist, using the first: %s"
msgstr "plusieurs fixed_ips existent, utilisation de la première : %s"

#: nova/api/metadata/handler.py:114
msgid ""
"X-Instance-ID present in request headers. The 'service_metadata_proxy' "
"option must be enabled to process this header."
msgstr ""
"X-instance-ID est présent dans les en-têtes de requêtes. L'option 'service-"
"metadata-proxy' doit être activée pour traiter ces en-têtes."

#: nova/api/metadata/handler.py:189
#, python-format
msgid ""
"X-Instance-ID-Signature: %(signature)s does not match the expected value: "
"%(expected_signature)s for id: %(instance_id)s. Request From: "
"%(remote_address)s"
msgstr ""

#: nova/api/metadata/handler.py:217
#, python-format
msgid ""
"Tenant_id %(tenant_id)s does not match tenant_id of instance %(instance_id)s."
msgstr ""
"Tenant_id %(tenant_id)s ne correspond pas avec le tenant_id de l'instance "
"%(instance_id)s."

#: nova/api/metadata/vendordata_json.py:47
#, python-format
msgid "%(logprefix)sfile does not exist"
msgstr "Le fichier %(logprefix)s n'existe pas"

#: nova/api/metadata/vendordata_json.py:50
#, python-format
msgid "%(logprefix)unexpected IOError when reading"
msgstr "%(logprefix)u IOError inattendue lors de la lecture"

#: nova/api/metadata/vendordata_json.py:54
#, python-format
msgid "%(logprefix)sfailed to load json"
msgstr "%(logprefix)s a échoué à charger json"

#: nova/api/openstack/__init__.py:236 nova/api/openstack/__init__.py:438
#, python-format
msgid ""
"Extension %(ext_name)s: Cannot extend resource %(collection)s: No such "
"resource"
msgstr ""
"Extension %(ext_name)s : impossible d'étendre la ressource %(collection)s : "
"aucune ressource"

#: nova/api/openstack/__init__.py:289
#: nova/api/openstack/compute/plugins/v3/servers.py:109
#, python-format
msgid "Not loading %s because it is in the blacklist"
msgstr "Pas de chargement de %s car il est la liste noire"

#: nova/api/openstack/__init__.py:294
#: nova/api/openstack/compute/plugins/v3/servers.py:114
#, python-format
msgid "Not loading %s because it is not in the whitelist"
msgstr "Pas de chargement de %s car il n'est pas dans la liste blanche"

#: nova/api/openstack/__init__.py:314
#, python-format
msgid "Extensions in both blacklist and whitelist: %s"
msgstr "Extensions à la fois dans la liste noire et la liste blanche : %s"

#: nova/api/openstack/common.py:498
msgid "Rejecting snapshot request, snapshots currently disabled"
msgstr "Rejet de la demande d'instantané, instantanés actuellement désactivés"

#: nova/api/openstack/extensions.py:278
#, python-format
msgid "Failed to load extension %(ext_factory)s: %(exc)s"
msgstr "Echec du chargement de l'extension %(ext_factory)s : %(exc)s"

#: nova/api/openstack/compute/servers.py:82
msgid ""
"XML support has been deprecated and may be removed as early as the Juno "
"release."
msgstr ""
"Le support XML est obsolète et sera peut-être supprimé dès la sortie de Juno."

#: nova/api/openstack/compute/views/servers.py:198
msgid "Instance has had its instance_type removed from the DB"
msgstr "instance_type de l'instance a été retiré de la BD"

#: nova/cells/manager.py:79
msgid ""
"The cells feature of Nova is considered experimental by the OpenStack "
"project because it receives much less testing than the rest of Nova. This "
"may change in the future, but current deployers should be aware that the use "
"of it in production right now may be risky."
msgstr ""

#: nova/cells/messaging.py:1213
#, python-format
msgid "No match when trying to update BDM: %(bdm)s"
msgstr "Pas de correspondance en essayant de mettre à jour BDM : %(bdm)s"

#: nova/cells/messaging.py:1694
#, python-format
msgid "No cell_name for %(method)s() from API"
msgstr "Pas de cell_name pour %(method)s() de l'API "

#: nova/cells/messaging.py:1711
msgid "No cell_name for instance update from API"
msgstr "Pas de cell_name pour la mise à jour de l'instance de l'API"

#: nova/cells/weights/mute_child.py:66
#, python-format
msgid ""
"%(cell)s has not been seen since %(last_seen)s and is being treated as mute."
msgstr ""

#: nova/compute/manager.py:1240
#, python-format
msgid ""
"Treating negative config value (%(retries)s) for 'block_device_retries' as 0."
msgstr ""
"Traitement de la valeur de configuration négative (%(retries)s) pour "
"'block_device_retries' à 0."

#: nova/compute/manager.py:1839
msgid ""
"Failed to create block device for instance due to being over volume resource "
"quota"
msgstr ""
"Échec à créer des périphériques par blocs pour une instance ceci au dû au "
"dépassement du quota de ressource pour le volume"

#: nova/compute/manager.py:2136
msgid "No more network or fixed IP to be allocated"
msgstr "Aucun réseau ou adresse IP fixes ne peuvent être alloués"

#: nova/compute/manager.py:2412
#, python-format
msgid "Ignoring EndpointNotFound: %s"
msgstr "EndpointNotFound ignorée : %s"

#: nova/compute/manager.py:2430
#, python-format
msgid "Failed to delete volume: %(volume_id)s due to %(exc)s"
msgstr "Echec à supprimer le volume : %(volume_id)s à cause de %(exc)s"

#: nova/compute/manager.py:4599
#, python-format
msgid ""
"Ignoring DiskNotFound exception while detaching volume %(volume_id)s from "
"%(mp)s: %(err)s"
msgstr ""
"Exception Disque Non Trouvé ignorée pendant le détachement volume "
"%(volume_id)s depuis %(mp)s : %(err)s  "

#: nova/compute/manager.py:5834
#, python-format
msgid ""
"Instance shutdown by itself. Calling the stop API. Current vm_state: "
"%(vm_state)s, current task_state: %(task_state)s, current DB power_state: "
"%(db_power_state)s, current VM power_state: %(vm_power_state)s"
msgstr ""
"Instance close par elle-même. Appel de l'API d'arrêt. vm_state courant : "
"%(vm_state)s, task_state courant : %(task_state)s, DB power_state courant : "
"%(db_power_state)s, VM power_state courant : %(vm_power_state)s"

#: nova/compute/manager.py:5889
#, python-format
msgid ""
"Instance is not stopped. Calling the stop API. Current vm_state: "
"%(vm_state)s, current task_state: %(task_state)s, current DB power_state: "
"%(db_power_state)s, current VM power_state: %(vm_power_state)s"
msgstr ""
"L'instance n'est pas arrêtée. Appel de l'API d'arrêt. vm_state courant : "
"%(vm_state)s, task_state courant : %(task_state)s, DB power_state courant : "
"%(db_power_state)s, VM power_state courant : %(vm_power_state)s"

#: nova/compute/utils.py:222
#, python-format
msgid "Can't access image %(image_id)s: %(error)s"
msgstr "Impossible d'accéder à l'image %(image_id)s : %(error)s"

#: nova/compute/utils.py:252
#, python-format
msgid ""
"Metadata value %(value)s for %(key)s is not of type %(type)s. Using default "
"value %(default)s."
msgstr ""
"Valeur des métadonnées %(value)s pour %(key)s n'est pas du type %(type)s. "
"Utilisation de la valeur par défaut %(default)s."

#: nova/compute/utils.py:376
#, python-format
msgid ""
"No host name specified for the notification of HostAPI.%s and it will be "
"ignored"
msgstr ""
"Pas de nom d'hôte spécifié pour la notification de HostAPI.%s cela sera "
"ignoré."

#: nova/compute/resources/__init__.py:31
#, python-format
msgid "Compute resource plugin %s was not loaded"
msgstr "Le greffon de la ressource Compute %s n'a pas été chargé"

#: nova/conductor/api.py:320
msgid ""
"Timed out waiting for nova-conductor.  Is it running? Or did this service "
"start before nova-conductor?  Reattempting establishment of nova-conductor "
"connection..."
msgstr ""

#: nova/conductor/manager.py:733
msgid "No valid host found for unshelve instance"
msgstr ""

#: nova/conductor/manager.py:776
msgid "No valid host found for rebuild"
msgstr ""

#: nova/console/serial.py:98
#, python-format
msgid ""
"serial_console.port_range should be <num>:<num>. Given value %(port_range)s "
"could not be parsed. Taking the default port range %(default)s."
msgstr ""
"serial_console.port_range devrait être <num>:<num>. La valeur donnée "
"%(port_range)s ne peut être analysée. Prise en compte de la plage de ports "
"par défaut %(default)s."

#: nova/consoleauth/manager.py:84
#, python-format
msgid "Token: %(token)s failed to save into memcached."
msgstr "Jeton : %(token)s a échoué à sauvegarder dans memcached. "

#: nova/consoleauth/manager.py:95
#, python-format
msgid "Instance: %(instance_uuid)s failed to save into memcached"
msgstr "Instance: %(instance_uuid)s a échoué à sauvegarder dans le memcached"

#: nova/db/sqlalchemy/api.py:184
#, python-format
msgid "Deadlock detected when running '%(func_name)s': Retrying..."
msgstr ""
"Interblocage détecté lors de l'exécution de '%(func_name)s' : Nouvelle "
"tentative en cours..."

#: nova/db/sqlalchemy/api.py:3444
#, python-format
msgid "Change will make usage less than 0 for the following resources: %s"
msgstr ""

#: nova/keymgr/mock_key_mgr.py:54
msgid "This key manager is not suitable for use in production deployments"
msgstr ""

#: nova/keymgr/single_key_mgr.py:40
msgid ""
"This key manager is insecure and is not recommended for production "
"deployments"
msgstr ""

#: nova/keymgr/single_key_mgr.py:72
#, python-format
msgid "Not deleting key %s"
msgstr ""

#: nova/network/floating_ips.py:195
#, python-format
msgid "Address |%(address)s| is not allocated"
msgstr "L'adresse |%(address)s| n'est pas allouée"

#: nova/network/floating_ips.py:199
#, python-format
msgid "Address |%(address)s| is not allocated to your project |%(project)s|"
msgstr "L'adresse |%(address)s| n'est pas allouée à votre projet |%(project)s|"

#: nova/network/floating_ips.py:219
#, python-format
msgid "Quota exceeded for %s, tried to allocate floating IP"
msgstr ""

#: nova/network/floating_ips.py:376
#, python-format
msgid "Failed to disassociated floating address: %s"
msgstr ""

#: nova/network/floating_ips.py:541
#, python-format
msgid ""
"Floating ip address |%(address)s| no longer belongs to instance "
"%(instance_uuid)s. Will not migrate it "
msgstr ""

#: nova/network/floating_ips.py:578
#, python-format
msgid ""
"Floating ip address |%(address)s| no longer belongs to instance "
"%(instance_uuid)s. Will not setup it."
msgstr ""

#: nova/network/floating_ips.py:622
#, python-format
msgid ""
"Database inconsistency: DNS domain |%s| is registered in the Nova db but not "
"visible to either the floating or instance DNS driver. It will be ignored."
msgstr ""
"Incohérence de base de données : Le domaine DNS |%s| est enregistré dans la "
"BD Nova mais non visible par le pilote DNS flottant ou d'instance. Il sera "
"ignoré."

#: nova/network/floating_ips.py:662
#, python-format
msgid "Domain |%(domain)s| already exists, changing zone to |%(av_zone)s|."
msgstr ""
"Le domaine |%(domain)s| existe déjà, définition de zone sur |%(av_zone)s|."

#: nova/network/floating_ips.py:671
#, python-format
msgid "Domain |%(domain)s| already exists, changing project to |%(project)s|."
msgstr ""
"Le domaine |%(domain)s| existe déjà, définition de projet sur |%(project)s|."

#: nova/network/ldapdns.py:108
#, python-format
msgid ""
"Found multiple matches for domain %(domain)s.\n"
"%(entry)s"
msgstr ""
"Plusieurs correspondances trouvées pour le domaine %(domain)s\n"
"%(entry)s"

#: nova/network/ldapdns.py:135
#, python-format
msgid "Unable to dequalify.  %(name)s is not in %(domain)s.\n"
msgstr "Disqualification impossible. %(name)s n'est pas dans %(domain)s.\n"

#: nova/network/ldapdns.py:376
msgid "This shouldn't be getting called except during testing."
msgstr "Le programme ne doit pas être appelé sauf pendant le test."

#: nova/network/linux_net.py:235
#, python-format
msgid "Attempted to remove chain %s which does not exist"
msgstr "Tentative de retrait de la chaîne %s qui n'existe pas"

#: nova/network/linux_net.py:304
#, python-format
msgid ""
"Tried to remove rule that was not there: %(chain)r %(rule)r %(wrap)r %(top)r"
msgstr ""
"Tentative de retrait de la règle qui n'était pas là : %(chain)r %(rule)r "
"%(wrap)r %(top)r"

#: nova/network/linux_net.py:1669
#, python-format
msgid "%s failed. Not Retrying."
msgstr ""

#: nova/network/linux_net.py:1672
#, python-format
msgid "%s failed. Retrying."
msgstr ""

#: nova/network/manager.py:813
#, python-format
msgid "instance-dns-zone not found |%s|."
msgstr "nstance-dns-zone non trouvé  |%s|."

#: nova/network/manager.py:820
#, python-format
msgid ""
"instance-dns-zone is |%(domain)s|, which is in availability zone |%(zone)s|. "
"Instance is in zone |%(zone2)s|. No DNS record will be created."
msgstr ""
"instance-dns-zone est |%(domain)s|, ce qui se trouve dans la zone de "
"disponibilité |%(zone)s|. L'instance est dans la zone |%(zone2)s|. Aucun "
"enregistrement DNS ne sera créé."

#: nova/network/manager.py:863
#, python-format
msgid ""
"Quota exceeded for project %(pid)s, tried to allocate fixed IP. %(used)s of "
"%(allowed)s are in use or are already reserved."
msgstr ""
"Quota dépassé pour le projet %(pid)s, essayé d'allouer une adresse IP fixe. "
"%(used)s de %(allowed)s sont utilisés ou déjà réservés."

#: nova/network/manager.py:951
msgid "Error cleaning up fixed ip allocation. Manual cleanup may be required."
msgstr ""

#: nova/network/manager.py:1053
#, python-format
msgid "Failed to rollback quota for deallocate fixed ip: %s"
msgstr "Échec à diminuer le quota pour désallouer une ip fixe : %s"

#: nova/network/manager.py:1066
#, python-format
msgid "IP %s leased that is not associated"
msgstr "Adresse IP %s spécialisée qui n'est pas associée"

#: nova/network/manager.py:1072
#, python-format
msgid "IP |%s| leased that isn't allocated"
msgstr "Adresse IP |%s| spécialisée qui n'est pas allouée"

#: nova/network/manager.py:1081
#, python-format
msgid "IP %s released that is not associated"
msgstr "Adresse IP %s publiée qui n'est pas associée"

#: nova/network/manager.py:1085
#, python-format
msgid "IP %s released that was not leased"
msgstr "IP %s libérée qui n'était pas allouée"

#: nova/network/minidns.py:122
#, python-format
msgid "Cannot delete entry |%s|"
msgstr "Impossible de supprimer l'entrée |%s|"

#: nova/network/minidns.py:207
#, python-format
msgid "Cannot delete domain |%s|"
msgstr "Impossible de supprimer le domaine |%s|"

#: nova/network/neutronv2/api.py:187
#, python-format
msgid "Neutron error: Fixed IP %s is already in use."
msgstr "Erreur Neutron: IP %s est déja utilisé."

#: nova/network/neutronv2/api.py:192
#, python-format
msgid "Neutron error: Port quota exceeded in tenant: %s"
msgstr "Erreur Neutron : Quota de Port dépassé dans le tenant : %s"

#: nova/network/neutronv2/api.py:197
#, python-format
msgid "Neutron error: No more fixed IPs in network: %s"
msgstr "Erreur Neutron : Plus d'adresse IP fixes dans le réseau : %s"

#: nova/network/neutronv2/api.py:201
#, python-format
msgid ""
"Neutron error: MAC address %(mac)s is already in use on network %(network)s."
msgstr ""
"Erreur Neutron : l'adresse MAC %(mac)s est déjà utilisée dans le réseau "
"%(network)s. "

#: nova/network/neutronv2/api.py:301
msgid "No network configured!"
msgstr "Aucun réseau configuré !"

#: nova/network/neutronv2/api.py:501
#, python-format
msgid "Port %s does not exist"
msgstr "Le port %s n'existe pas"

#: nova/network/neutronv2/api.py:505
#, python-format
msgid "Failed to delete port %s for instance."
msgstr "Echec dans la suppression du port %s pour cette instance."

#: nova/network/neutronv2/api.py:1278
#, python-format
msgid ""
"Network %(id)s not matched with the tenants network! The ports tenant "
"%(tenant_id)s will be used."
msgstr ""
"Le réseau %(id)s ne correspond pas avec le réseau des tenants! Les ports des "
"tenants %(tenant_id)s seront utilisés."

#: nova/network/security_group/neutron_driver.py:431
#, python-format
msgid ""
"Cannot add security group %(name)s to %(instance)s since the port "
"%(port_id)s does not meet security requirements"
msgstr ""
"Impossible d'ajouter le groupe de sécurité %(name)s à l'instance "
"%(instance)s car le port %(port_id)s ne respecte pas les exigences en "
"matière de sécurité"

#: nova/openstack/common/loopingcall.py:87
#, python-format
msgid "task %(func_name)s run outlasted interval by %(delay).2f sec"
msgstr ""
"L'exécution de la tâche %(func_name)s a dépassé intervalle de %(delay).2f "
"secondes "

#: nova/openstack/common/policy.py:254
#, python-format
msgid "Can not find policy directory: %s"
msgstr ""

#: nova/openstack/common/service.py:356
#, python-format
msgid "pid %d not in child list"
msgstr "PID %d absent de la liste d'enfants"

#: nova/pci/manager.py:112
#, python-format
msgid ""
"Trying to remove device with %(status)s ownership %(instance_uuid)s because "
"of %(pci_exception)s"
msgstr ""

#: nova/scheduler/driver.py:56
#, python-format
msgid "NoValidHost exception with message: '%s'"
msgstr "Exception NoValidHost avec le message : '%s'"

#: nova/scheduler/driver.py:62 nova/scheduler/utils.py:93
#, python-format
msgid "Setting instance to %s state."
msgstr "Positionnement de l'instance à l'état %s."

#: nova/scheduler/filter_scheduler.py:182
msgid "Instance disappeared during scheduling"
msgstr "L'instance a disparu pendant la programmation"

#: nova/scheduler/host_manager.py:170
#, python-format
msgid "Metric name unknown of %r"
msgstr "Nom de la mesure inconnu de %r"

#: nova/scheduler/host_manager.py:185
#: nova/tests/unit/scheduler/test_host_manager.py:285
#, python-format
msgid ""
"Host %(hostname)s has more disk space than database expected (%(physical)sgb "
"> %(database)sgb)"
msgstr ""
"L'hôte %(hostname)s a plus d'espace disque que ce qui est attendue par la "
"base de donnée (%(physical)sgo > %(database)sgo)"

#: nova/scheduler/host_manager.py:404
#: nova/tests/unit/scheduler/test_host_manager.py:291
#, python-format
msgid "No service for compute ID %s"
msgstr "Aucun service pour l'ID de calcul %s"

#: nova/scheduler/utils.py:77
#, python-format
msgid "Failed to %(service)s_%(method)s: %(ex)s"
msgstr "Échec de %(service)s_%(method)s : %(ex)s"

#: nova/scheduler/utils.py:233
#, python-format
msgid "Ignoring the invalid elements of the option %(name)s: %(options)s"
msgstr "Ignoré les éléments invalides de l'option %(name)s : %(options)s "

#: nova/scheduler/filters/compute_filter.py:47
#, python-format
msgid "%(host_state)s has not been heard from in a while"
msgstr "%(host_state)s n'a pas été entendu depuis un certain temps"

#: nova/scheduler/filters/core_filter.py:51
#: nova/scheduler/filters/exact_core_filter.py:36
msgid "VCPUs not set; assuming CPU collection broken"
msgstr "VCPU non défini ; collection CPU peut-être rompue"

#: nova/scheduler/filters/core_filter.py:102
#, python-format
msgid "Could not decode cpu_allocation_ratio: '%s'"
msgstr "Impossible de décoder cpi_allocation_ratio : '%s'"

#: nova/scheduler/filters/disk_filter.py:87
#, python-format
msgid "Could not decode disk_allocation_ratio: '%s'"
msgstr "Impossible de décoder disk_allocation_ratio : '%s'"

#: nova/scheduler/filters/io_ops_filter.py:76
#, python-format
msgid "Could not decode max_io_ops_per_host: '%s'"
msgstr "Impossible de décoder max_io_ops_per_host : '%s'"

#: nova/scheduler/filters/num_instances_filter.py:71
#, python-format
msgid "Could not decode max_instances_per_host: '%s'"
msgstr "Impossible de décoder max_instances_per_host : '%s'"

#: nova/scheduler/filters/ram_filter.py:95
#, python-format
msgid "Could not decode ram_allocation_ratio: '%s'"
msgstr "Impossible de décoder ram_allocation_ratio : '%s'"

#: nova/servicegroup/api.py:88
#, python-format
msgid ""
"Report interval must be less than service down time. Current config: "
"<service_down_time: %(service_down_time)s, report_interval: "
"%(report_interval)s>. Setting service_down_time to: %(new_service_down_time)s"
msgstr ""

#: nova/storage/linuxscsi.py:101
#, python-format
msgid "Multipath call failed exit (%(code)s)"
msgstr "L'appel multi-chemin a échoué sa sortie (%(code)s)"

#: nova/storage/linuxscsi.py:122
#, python-format
msgid "Couldn't find multipath device %s"
msgstr "Impossible de trouver le périphérique multi-chemin %s"

#: nova/storage/linuxscsi.py:131
#, python-format
msgid "Skip faulty line \"%(dev_line)s\" of multipath device %(mdev)s"
msgstr ""
"Passer la mauvaise ligne \"%(dev_line)s\" du périphérique multi-chemin "
"%(mdev)s"

#: nova/virt/configdrive.py:178
#, python-format
msgid "Image config drive option %(image_prop)s is invalid and will be ignored"
msgstr ""
"L'option de l'image de l'unité de configuration %(image_prop)s est invalide "
"et sera ignorée"

#: nova/virt/disk/api.py:366
#, python-format
msgid "Ignoring error injecting data into image %(image)s (%(e)s)"
msgstr ""
"Erreur sur l'injection de données ignorée dans l'image %(image)s (%(e)s)"

#: nova/virt/disk/api.py:456
#, python-format
msgid "Ignoring error injecting %(inject)s into image (%(e)s)"
msgstr "Erreur ignorée lors de l'injection de %(inject)s dans l'image (%(e)s)"

#: nova/virt/disk/vfs/guestfs.py:88
msgid ""
"Please consider to execute setup before trying to configure debug log "
"message."
msgstr ""
"Veuillez lancer l'installation avant d'essayer de configurer le message du "
"journal de debug. "

#: nova/virt/disk/vfs/guestfs.py:192
#, python-format
msgid "Unable to force TCG mode, libguestfs too old? %s"
msgstr "Incapable de forcer le mode TCG, libguestfs trop ancienne? %s"

#: nova/virt/hyperv/vmops.py:458
msgid "Timed out while waiting for soft shutdown."
msgstr "Temps dépassé durant l'attente de l'arrêt logiciel."

#: nova/virt/hyperv/vmutils.py:444
#, python-format
msgid ""
"Disk not found on controller \"%(controller_path)s\" with address "
"\"%(address)s\""
msgstr ""
"Disque non trouvé sur le contrôleur \"%(controller_path)s\" avec l'adresse "
"\"%(address)s\""

#: nova/virt/ironic/driver.py:104
#, python-format
msgid "Power state %s not found."
msgstr "État de l'alimentation %s non trouvé."

#: nova/virt/ironic/driver.py:205
#, python-format
msgid "cpu_arch not defined for node '%s'"
msgstr "cpu_arch n'est pas défini pour le nœud '%s'"

#: nova/virt/ironic/driver.py:233
#, python-format
msgid "Ignoring malformed capability '%s'. Format should be 'key:val'."
msgstr "Capacité mal formé ignorée '%s'. Le format devrait être 'key:val'."

#: nova/virt/ironic/driver.py:531
#, python-format
msgid "Warning, memory usage is 0 for %(instance)s on baremetal node %(node)s."
msgstr ""
"Avertissement, l'utilisation de la mémoire  est 0 pour %(instance)s sur le "
"nœud baremetal %(node)s."

#: nova/virt/ironic/driver.py:538
#, python-format
msgid ""
"Warning, number of cpus is 0 for %(instance)s on baremetal node %(node)s."
msgstr ""
"Avertissement, le nombre de cpus est 0 pour %(instance)s sur le nœud "
"baremetal %(node)s."

#: nova/virt/ironic/driver.py:726
#, python-format
msgid "Destroy called on non-existing instance %s."
msgstr "Destruction appelée sur une instance inexistante %s."

#: nova/virt/libvirt/driver.py:431
#, python-format
msgid "Invalid cachemode %(cache_mode)s specified for disk type %(disk_type)s."
msgstr ""
"Mode de mise en cache non valide %(cache_mode)s spécifié pour le type de "
"disque %(disk_type)s."

#: nova/virt/libvirt/driver.py:722
#, python-format
msgid ""
"The libvirt driver is not tested on %(type)s/%(arch)s by the OpenStack "
"project and thus its quality can not be ensured. For more information, see: "
"https://wiki.openstack.org/wiki/HypervisorSupportMatrix"
msgstr ""
"Le pilote libvirt n'est pas testé sur %(type)s/%(arch)s par le projet "
"OpenStack et sa qualité ne peut donc être garantie. Pour plus "
"d'informations, voir : https://wiki.openstack.org/wiki/"
"HypervisorSupportMatrix"

#: nova/virt/libvirt/driver.py:739
msgid ""
"Running libvirt-lxc without user namespaces is dangerous. Containers spawned "
"by Nova will be run as the host's root user. It is highly suggested that "
"user namespaces be used in a public or multi-tenant environment."
msgstr ""
"Exécuter libvirt-lxc sans espaces de nom utilisateur est dangereux. Les "
"conteneurs générés par Nova seront lancés comme utilisateur hôte root. Il "
"est fortement conseillé que les espaces de nom soient utilisés dans un "
"environnement publique ou à plusieurs projets."

#: nova/virt/libvirt/driver.py:788
#, python-format
msgid "URI %(uri)s does not support events: %(error)s"
msgstr "URI %(uri)s ne supportent pas les événements : %(error)s"

#: nova/virt/libvirt/driver.py:804
#, python-format
msgid "URI %(uri)s does not support connection events: %(error)s"
msgstr "URI %(uri)s ne supporte pas les événements de connexion  : %(error)s"

#: nova/virt/libvirt/driver.py:1035
msgid "Cannot destroy instance, operation time out"
msgstr "Impossible de détruire l'instance, l'opération a expiré"

#: nova/virt/libvirt/driver.py:1059
msgid "During wait destroy, instance disappeared."
msgstr "Lors de la destruction de l'attente, l'instance a disparu."

#: nova/virt/libvirt/driver.py:1146
msgid "Instance may be still running, destroy it again."
msgstr ""
"L'instance est peut-être encore en cours d'exécution, détruisez-la de "
"nouveau."

#: nova/virt/libvirt/driver.py:1201
#, python-format
msgid "Ignoring Volume Error on vol %(vol_id)s during delete %(exc)s"
msgstr ""
"Erreur Volume Ignorée sur le volume %(vol_id)s durant la suppression de "
"%(exc)s"

#: nova/virt/libvirt/driver.py:1557 nova/virt/libvirt/driver.py:1565
msgid "During detach_volume, instance disappeared."
msgstr "Pendant l'opération detach_volume, l'instance a disparu."

#: nova/virt/libvirt/driver.py:1610
msgid "During detach_interface, instance disappeared."
msgstr "L'instance a disparu lord de l'opération detach_interface."

#: nova/virt/libvirt/driver.py:2286
msgid "Failed to soft reboot instance. Trying hard reboot."
msgstr ""
"Échec dans le redémarrage logiciel de l'instance. Essayez un redémarrage "
"matériel."

#: nova/virt/libvirt/driver.py:2926
#, python-format
msgid "Image %s not found on disk storage. Continue without injecting data"
msgstr ""
"L'image %s n'est pas trouvée sur l'espace disque. Continuer sans injonction "
"de données."

#: nova/virt/libvirt/driver.py:3112
msgid "File injection into a boot from volume instance is not supported"
msgstr ""
"L'injection de fichier dans le démarrage d'une instance de volume n'est pas "
"supportée."

#: nova/virt/libvirt/driver.py:3187
msgid "Instance disappeared while detaching a PCI device from it."
msgstr "L'instance disparaît quand le périphérique PCI se sépare de celle-ci."

#: nova/virt/libvirt/driver.py:3307
#, python-format
msgid "Cannot update service status on host: %s,since it is not registered."
msgstr ""
"Impossible de mettre à jour le statut du service sur l'hôte : %s, car il "
"n'est pas enregistré."

#: nova/virt/libvirt/driver.py:3310
#, python-format
msgid ""
"Cannot update service status on host: %s,due to an unexpected exception."
msgstr ""
"Impossible de mettre à jour le statut du service sur l'hôte : %s, en raison "
"d'une exception inattendue."

#: nova/virt/libvirt/driver.py:3338
#, python-format
msgid "URI %(uri)s does not support full set of host capabilities: %(error)s"
msgstr ""
"L'URI %(uri)s ne supporte pas l'ensemble complet des possibilités de "
"l'hôte : %(error)s"

#: nova/virt/libvirt/driver.py:3650
msgid "Too many id maps, only included first five."
msgstr "Trop de cartes id, inclure uniquement les cinq premières."

#: nova/virt/libvirt/driver.py:3660
#, python-format
msgid "Invalid value for id mapping %s"
msgstr "Valeur invalide pour la configuration d'id %s"

#: nova/virt/libvirt/driver.py:4183
msgid ""
"Old property name \"hw_watchdog_action\" is now deprecated and will be "
"removed in the next release. Use updated property name \"hw:watchdog_action"
"\" instead"
msgstr ""
"L'ancien nom de propriété \"hw_watchdog_action\" est maintenant obsolète et "
"sera retiré dans la prochaine version. Utiliser à la place le nom de "
"propriété mis à jour \"hw:watchdog_action\""

#: nova/virt/libvirt/driver.py:4514
#, python-format
msgid "Timeout waiting for vif plugging callback for instance %(uuid)s"
msgstr ""
"Dépassement du délai d'attente pour le rappel de la connexion int. virt., "
"pour l'instance %(uuid)s"

#: nova/virt/libvirt/driver.py:4535
#, python-format
msgid "couldn't obtain the XML from domain: %(uuid)s, exception: %(ex)s"
msgstr ""
"Impossible d'obtenir  de l'XML depuis le domaine : %(uuid)s, exception : "
"%(ex)s"

#: nova/virt/libvirt/driver.py:4592
msgid ""
"Cannot get the number of cpu, because this function is not implemented for "
"this platform. "
msgstr ""
"Impossible d'obtenir le nombre d'UC, car cette fonction n'est pas "
"implémentée pour cette plateforme. "

#: nova/virt/libvirt/driver.py:4654
#, python-format
msgid ""
"couldn't obtain the vpu count from domain id: %(uuid)s, exception: %(ex)s"
msgstr ""
"Impossible d'obtenir le compte de vpu depuis l'id du domaine : %(uuid)s, "
"exception : %(ex)s"

#: nova/virt/libvirt/driver.py:4685
#, python-format
msgid "couldn't obtain the memory from domain: %(uuid)s, exception: %(ex)s"
msgstr ""
"Impossible d'obtenir de la mémoire depuis le domaine : %(uuid)s, exception : "
"%(ex)s"

#: nova/virt/libvirt/driver.py:4890
#, python-format
msgid "URI %(uri)s does not support listDevices: %(error)s"
msgstr "l'URI %(uri)s ne supporte pas la liste de périphériques : %(error)s"

#: nova/virt/libvirt/driver.py:5522
#, python-format
msgid ""
"An error occurred trying to live migrate. Falling back to legacy live "
"migrate flow. Error: %s"
msgstr ""
"Une erreur est survenue en essayant de migrer directement. Retour au flux "
"normal de migration directe. Erreur : %s"

#: nova/virt/libvirt/driver.py:5660
#, python-format
msgid "plug_vifs() failed %(cnt)d. Retry up to %(max_retry)d."
msgstr "Échec de plug_vifs() %(cnt)d. Recommencer jusqu'à %(max_retry)d."

#: nova/virt/libvirt/driver.py:5873
#, python-format
msgid ""
"Error from libvirt while getting description of %(instance_name)s: [Error "
"Code %(error_code)s] %(ex)s"
msgstr ""
"Erreur de libvirt lors de l'obtention de la description de "
"%(instance_name)s : [Code d'erreur %(error_code)s] %(ex)s"

#: nova/virt/libvirt/driver.py:5881
#, python-format
msgid ""
"Periodic task is updating the host stat, it is trying to get disk "
"%(i_name)s, but disk file was removed by concurrent operations such as "
"resize."
msgstr ""
"Une tâche périodique met à jour le statut de l'hôte, elle essaye d'avoir le "
"disque %(i_name)s, mais le fichier disque a été supprimé par une opérations "
"simultané comme un redimensionnement."

#: nova/virt/libvirt/driver.py:5887
#, python-format
msgid ""
"Periodic task is updating the host stat, it is trying to get disk "
"%(i_name)s, but access is denied. It is most likely due to a VM that exists "
"on the compute node but is not managed by Nova."
msgstr ""
"Une tâche périodique met à jour le statut de l'hôte, elle essaye d'avoir le "
"disque %(i_name)s, mais l'accès lui est refusé. Cela est très probablement "
"due à une VM qui existe sur le nœud calcul mais non géré par Nova."

#: nova/virt/libvirt/driver.py:5896
#, python-format
msgid ""
"Periodic task is updating the host stats, it is trying to get disk info for "
"%(i_name)s, but the backing volume block device was removed by concurrent "
"operations such as resize. Error: %(error)s"
msgstr ""
"Une tâche périodique met à jour les statuts des hôtes, elle essaye d'accéder "
"aux informations du disque de %(i_name)s, mais la sauvegarde du périphérique "
"du volume par bloc a été supprimée par une opérations parallèles comme un "
"redimensionnement. Erreur : %(error)s"

#: nova/virt/libvirt/firewall.py:53
msgid ""
"Libvirt module could not be loaded. NWFilterFirewall will not work correctly."
msgstr ""
"Impossible de charger le module libvirt. NWFilterFirewall ne fonctionnera "
"pas correctement."

#: nova/virt/libvirt/imagecache.py:330
#, python-format
msgid ""
"Instance %(instance)s is using a backing file %(backing)s which does not "
"appear in the image service"
msgstr ""
"L'instance %(instance)s utilise un fichier de sauvegarde %(backing)s qui "
"n'apparaît pas dans le service d'image"

#: nova/virt/libvirt/imagecache.py:522
#, python-format
msgid ""
"image %(id)s at (%(base_file)s): warning -- an absent base file is in use! "
"instances: %(instance_list)s"
msgstr ""
"image %(id)s à (%(base_file)s) : avertissement -- un fichier de base absent "
"est en cours d'utilisation ! instances : %(instance_list)s"

#: nova/virt/libvirt/imagecache.py:562
#, python-format
msgid "%s swap image was used by instance but no back files existing!"
msgstr ""

#: nova/virt/libvirt/imagecache.py:588
#, python-format
msgid "Unknown base file: %s"
msgstr "Fichier de base inconnu : %s"

#: nova/virt/libvirt/lvm.py:104
#, python-format
msgid ""
"Volume group %(vg)s will not be able to hold sparse volume %(lv)s. Virtual "
"volume size is %(size)db, but free space on volume group is only "
"%(free_space)db."
msgstr ""
"Le groupe de volumes %(vg)s ne pourra pas contenir le volume incomplet "
"%(lv)s. La taille du volume virtuel est de %(size)db, mais l'espace libre "
"sur le groupe de volumes est de seulement %(free_space)db."

#: nova/virt/libvirt/rbd_utils.py:269
#, python-format
msgid "rbd remove %(volume)s in pool %(pool)s failed"
msgstr "La suppression de rbd %(volume)s dans  le pool %(pool)s a échoué"

#: nova/virt/libvirt/utils.py:71 nova/virt/libvirt/utils.py:77
msgid "systool is not installed"
msgstr "systool n'est pas installé"

#: nova/virt/libvirt/volume.py:133
#, python-format
msgid "Unknown content in connection_info/qos_specs: %s"
msgstr "Contenu inconnu dans connection_info/qos_specs : %s"

#: nova/virt/libvirt/volume.py:332
#, python-format
msgid ""
"ISCSI volume not yet found at: %(disk_dev)s. Will rescan & retry.  Try "
"number: %(tries)s"
msgstr ""
"Volume ISCSI pas encore trouvé à : %(disk_dev)s. Nouvelle analyse et "
"nouvelle tentative. Nombre de tentatives : %(tries)s"

#: nova/virt/libvirt/volume.py:403
#, python-format
msgid "Unable to delete volume device %s"
msgstr "Incapable de supprimer le périphérique du volume %s"

#: nova/virt/libvirt/volume.py:414
#, python-format
msgid ""
"Failed to remove multipath device descriptor %(dev_mapper)s. Exception "
"message: %(msg)s"
msgstr ""
"Echec à supprimer le descriptif du périphérique multi-chemin %(dev_mapper)s. "
"Message d'exception : %(msg)s"

#: nova/virt/libvirt/volume.py:748 nova/virt/libvirt/volume.py:922
#, python-format
msgid "%s is already mounted"
msgstr "%s est déjà monté"

#: nova/virt/libvirt/volume.py:809
#, python-format
msgid "AoE volume not yet found at: %(aoedevpath)s. Try number: %(tries)s"
msgstr ""
"Volume AoE pas encore trouvé à : %(aoedevpath)s. Nombre de tentatives : "
"%(tries)s"

#: nova/virt/libvirt/volume.py:1019
#, python-format
msgid ""
"Fibre volume not yet found at: %(mount_device)s. Will rescan & retry.  Try "
"number: %(tries)s"
msgstr ""
"Volume de fibre pas encore trouvé à : %(mount_device)s. Nouvelle analyse et "
"nouvelle tentative. Nombre de tentatives : %(tries)s"

#: nova/virt/libvirt/volume.py:1075
#, python-format
msgid "multipath-tools probably work improperly. devices to remove = %s."
msgstr ""
"L'outil de multi-chemin fonctionne probablement mal. Périphériques à "
"supprimer = %s."

#: nova/virt/libvirt/volume.py:1129
msgid "Value required for 'scality_sofs_config'"
msgstr "Valeur requise pour 'scality_sofs_config'"

#: nova/virt/libvirt/volume.py:1140
#, python-format
msgid "Cannot access 'scality_sofs_config': %s"
msgstr "Impossible d'accéder à 'scality_sofs_config' : %s"

#: nova/virt/libvirt/volume.py:1146
msgid "Cannot execute /sbin/mount.sofs"
msgstr "Impossible d'exécuter /sbin/mount.sofs"

#: nova/virt/libvirt/volume.py:1161
msgid "Cannot mount Scality SOFS, check syslog for errors"
msgstr ""
"Impossible de monter Scality SOFS, consultez le fichier syslog pour voir les "
"erreurs"

#: nova/virt/vmwareapi/driver.py:163
#, python-format
msgid "The following clusters could not be found in the vCenter %s"
msgstr "Les clusters suivants ne peuvent pas être trouvés dans le vCenter %s"

#: nova/virt/vmwareapi/driver.py:206
msgid "datastore_regex is ignored when PBM is enabled"
msgstr "datastore_regex est ignoré quand PBM est activé"

#: nova/virt/vmwareapi/driver.py:251
msgid "Instance cannot be found in host, or in an unknownstate."
msgstr "L'instance ne peut être trouvée dans l'hôte ou dans un état inconnu."

#: nova/virt/vmwareapi/vm_util.py:1225
#, python-format
msgid ""
"vmware_ostype from image is not recognised: '%(ostype)s'. An invalid os type "
"may be one cause of this instance creation failure"
msgstr ""
"vmware_ostype depuis l'image n'est pas reconnue : '%(ostype)s'. Un type os "
"invalide peut être la cause de l'échec de la création d'une instance"

#: nova/virt/vmwareapi/vmops.py:343
#, python-format
msgid ""
"Destination %s already exists! Concurrent moves can lead to unexpected "
"results."
msgstr ""
"La destination %s existe déjà! Des déplacements parallèles peuvent conduire "
"à des résultats inattendus."

#: nova/volume/cinder.py:122
msgid ""
"Cinder V1 API is deprecated as of the Juno release, and Nova is still "
"configured to use it. Enable the V2 API in Cinder and set "
"cinder_catalog_info in nova.conf to use it."
msgstr ""
"L'API V1 Cinder est obsolète dans la version Juno et Nova est toujours "
"configuré pour s'en servir. Activer l'API V2 dans Cinder et positionner "
"cinder_catalog_info dans nova.conf pour l'utiliser."
