# Translations template for nova.
# Copyright (C) 2014 ORGANIZATION
# This file is distributed under the same license as the nova project.
#
# Translators:
msgid ""
msgstr ""
"Project-Id-Version: nova\n"
"Report-Msgid-Bugs-To: EMAIL@ADDRESS\n"
"POT-Creation-Date: 2014-08-12 06:05+0000\n"
"PO-Revision-Date: 2014-06-14 19:30+0000\n"
"Last-Translator: openstackjenkins <jenkins@openstack.org>\n"
"Language-Team: English (United Kingdom) (http://www.transifex.com/projects/p/"
"nova/language/en_GB/)\n"
"Language: en_GB\n"
"MIME-Version: 1.0\n"
"Content-Type: text/plain; charset=UTF-8\n"
"Content-Transfer-Encoding: 8bit\n"
"Generated-By: Babel 1.3\n"
"Plural-Forms: nplurals=2; plural=(n != 1);\n"

#: nova/hooks.py:84
#, python-format
msgid "Fatal Exception running %(name)s pre-hook: %(obj)s"
msgstr ""

#: nova/hooks.py:89
#, python-format
msgid "Exception running %(name)s pre-hook: %(obj)s"
msgstr ""

#: nova/hooks.py:105
#, python-format
msgid "Fatal Exception running %(name)s post-hook: %(obj)s"
msgstr ""

#: nova/hooks.py:110
#, python-format
msgid "Exception running %(name)s post-hook: %(obj)s"
msgstr ""

#: nova/api/ec2/__init__.py:244
#, python-format
msgid "Keystone failure: %s"
msgstr ""

#: nova/api/ec2/__init__.py:493
#, python-format
msgid "Unexpected %(ex_name)s raised: %(ex_str)s"
msgstr ""

#: nova/api/ec2/__init__.py:520
#, python-format
msgid "Environment: %s"
msgstr ""

#: nova/api/metadata/handler.py:155
#, python-format
msgid "Failed to get metadata for ip: %s"
msgstr ""

#: nova/api/metadata/handler.py:212
#, python-format
msgid "Failed to get metadata for instance id: %s"
msgstr ""

#: nova/api/openstack/common.py:134
#, python-format
msgid ""
"status is UNKNOWN from vm_state=%(vm_state)s task_state=%(task_state)s. Bad "
"upgrade or db corrupted?"
msgstr ""

#: nova/api/openstack/wsgi.py:684
#, python-format
msgid "Exception handling resource: %s"
msgstr ""

#: nova/api/openstack/compute/contrib/admin_actions.py:68
#, python-format
msgid "Compute.api::pause %s"
msgstr ""

#: nova/api/openstack/compute/contrib/admin_actions.py:90
#, python-format
msgid "Compute.api::unpause %s"
msgstr ""

#: nova/api/openstack/compute/contrib/admin_actions.py:112
#, python-format
msgid "compute.api::suspend %s"
msgstr ""

#: nova/api/openstack/compute/contrib/admin_actions.py:134
#, python-format
msgid "compute.api::resume %s"
msgstr ""

#: nova/api/openstack/compute/contrib/admin_actions.py:160
#, python-format
msgid "Error in migrate %s"
msgstr ""

#: nova/api/openstack/compute/contrib/admin_actions.py:179
#, python-format
msgid "Compute.api::reset_network %s"
msgstr ""

#: nova/api/openstack/compute/contrib/admin_actions.py:198
#, python-format
msgid "Compute.api::inject_network_info %s"
msgstr ""

#: nova/api/openstack/compute/contrib/admin_actions.py:215
#, python-format
msgid "Compute.api::lock %s"
msgstr ""

#: nova/api/openstack/compute/contrib/admin_actions.py:234
#, python-format
msgid "Compute.api::unlock %s"
msgstr ""

#: nova/api/openstack/compute/contrib/admin_actions.py:392
#, python-format
msgid "Compute.api::resetState %s"
msgstr ""

#: nova/api/openstack/compute/contrib/multinic.py:85
#, python-format
msgid "Unable to find address %r"
msgstr ""

#: nova/api/openstack/compute/contrib/os_tenant_networks.py:85
msgid "Failed to get default networks"
msgstr ""

#: nova/api/openstack/compute/contrib/os_tenant_networks.py:125
msgid "Failed to update usages deallocating network."
msgstr ""

#: nova/compute/api.py:561
msgid "Failed to set instance name using multi_instance_display_name_template."
msgstr ""

#: nova/compute/api.py:1429
msgid ""
"Something wrong happened when trying to delete snapshot from shelved "
"instance."
msgstr ""

#: nova/compute/api.py:3732
msgid "Failed to update usages deallocating security group"
msgstr ""

#: nova/compute/flavors.py:167
#, python-format
msgid "DB error: %s"
msgstr ""

#: nova/compute/flavors.py:178
#, python-format
msgid "Instance type %s not found for deletion"
msgstr ""

#: nova/compute/manager.py:366
#, python-format
msgid "Error while trying to clean up image %s"
msgstr ""

#: nova/compute/manager.py:755
msgid "Failed to check if instance shared"
msgstr ""

#: nova/compute/manager.py:821 nova/compute/manager.py:872
msgid "Failed to complete a deletion"
msgstr ""

#: nova/compute/manager.py:913
msgid "Failed to stop instance"
msgstr ""

#: nova/compute/manager.py:925
msgid "Failed to start instance"
msgstr ""

#: nova/compute/manager.py:950
msgid "Failed to revert crashed migration"
msgstr ""

#: nova/compute/manager.py:1364
msgid "Failed to dealloc network for deleted instance"
msgstr ""

#: nova/compute/manager.py:1385
msgid "Failed to dealloc network for failed instance"
msgstr ""

#: nova/compute/manager.py:1458 nova/compute/manager.py:3514
msgid "Error trying to reschedule"
msgstr ""

#: nova/compute/manager.py:1567
#, python-format
msgid "Instance failed network setup after %(attempts)d attempt(s)"
msgstr ""

#: nova/compute/manager.py:1755
msgid "Instance failed block device setup"
msgstr ""

#: nova/compute/manager.py:1775 nova/compute/manager.py:2116
#: nova/compute/manager.py:4058
msgid "Instance failed to spawn"
msgstr ""

#: nova/compute/manager.py:1957
msgid "Unexpected build failure, not rescheduling build."
msgstr ""

#: nova/compute/manager.py:2026 nova/compute/manager.py:2078
msgid "Failed to allocate network(s)"
msgstr ""

#: nova/compute/manager.py:2104
msgid "Failure prepping block device"
msgstr ""

#: nova/compute/manager.py:2137
msgid "Failed to deallocate networks"
msgstr ""

#: nova/compute/manager.py:2367 nova/compute/manager.py:3705
#: nova/compute/manager.py:5803
msgid "Setting instance vm_state to ERROR"
msgstr ""

#: nova/compute/manager.py:2579 nova/compute/manager.py:4914
#, python-format
msgid "Failed to get compute_info for %s"
msgstr ""

#: nova/compute/manager.py:3005
#, python-format
msgid "set_admin_password failed: %s"
msgstr ""

#: nova/compute/manager.py:3090
msgid "Error trying to Rescue Instance"
msgstr ""

#: nova/compute/manager.py:3711
#, python-format
msgid "Failed to rollback quota for failed finish_resize: %s"
msgstr ""

#: nova/compute/manager.py:4310
#, python-format
msgid "Failed to attach %(volume_id)s at %(mountpoint)s"
msgstr ""

#: nova/compute/manager.py:4349
#, python-format
msgid "Failed to detach volume %(volume_id)s from %(mp)s"
msgstr ""

#: nova/compute/manager.py:4422
#, python-format
msgid "Failed to swap volume %(old_volume_id)s for %(new_volume_id)s"
msgstr ""

#: nova/compute/manager.py:4429
#, python-format
msgid "Failed to connect to volume %(volume_id)s with volume at %(mountpoint)s"
msgstr ""

#: nova/compute/manager.py:4716
#, python-format
msgid "Pre live migration failed at %s"
msgstr ""

#: nova/compute/manager.py:5216
msgid "Periodic task failed to offload instance."
msgstr ""

#: nova/compute/manager.py:5256
#, python-format
msgid "Failed to generate usage audit for instance on host %s"
msgstr ""

#: nova/compute/manager.py:5446
msgid ""
"Periodic sync_power_state task had an error while processing an instance."
msgstr ""

#: nova/compute/manager.py:5549 nova/compute/manager.py:5558
#: nova/compute/manager.py:5589 nova/compute/manager.py:5600
msgid "error during stop() in sync_power_state."
msgstr ""

#: nova/objects/instance_fault.py:87
msgid "Failed to notify cells of instance fault"
msgstr "Failed to notify cells of instance fault"

#: nova/openstack/common/excutils.py:76
#, python-format
msgid "Original exception being dropped: %s"
msgstr "Original exception being dropped: %s"

#: nova/openstack/common/excutils.py:105
#, python-format
msgid "Unexpected exception occurred %d time(s)... retrying."
msgstr "Unexpected exception occurred %d time(s)... retrying."

#: nova/openstack/common/lockutils.py:119
#, python-format
msgid "Could not release the acquired lock `%s`"
msgstr ""

#: nova/openstack/common/loopingcall.py:95
msgid "in fixed duration looping call"
msgstr "in fixed duration looping call"

#: nova/openstack/common/loopingcall.py:138
msgid "in dynamic looping call"
msgstr "in dynamic looping call"

#: nova/openstack/common/periodic_task.py:202
#, python-format
msgid "Error during %(full_task_name)s: %(e)s"
msgstr "Error during %(full_task_name)s: %(e)s"

#: nova/openstack/common/policy.py:507
#, python-format
msgid "Failed to understand rule %s"
msgstr "Failed to understand rule %s"

#: nova/openstack/common/policy.py:517
#, python-format
msgid "No handler for matches of kind %s"
msgstr "No handler for matches of kind %s"

#: nova/openstack/common/policy.py:787
#, python-format
msgid "Failed to understand rule %r"
msgstr "Failed to understand rule %r"

#: nova/openstack/common/service.py:188
msgid "Exception during rpc cleanup."
msgstr "Exception during rpc cleanup."

#: nova/openstack/common/service.py:276
msgid "Unhandled exception"
msgstr "Unhandled exception"

#: nova/openstack/common/db/api.py:72
msgid "DB exceeded retry limit."
msgstr ""

#: nova/openstack/common/db/api.py:76
msgid "DB connection error."
msgstr ""

#: nova/openstack/common/db/sqlalchemy/session.py:460
msgid "DB exception wrapped."
msgstr "DB exception wrapped."

#: nova/openstack/common/db/sqlalchemy/test_migrations.py:267
#, python-format
msgid "Failed to migrate to version %s on engine %s"
msgstr ""

#: nova/pci/pci_stats.py:119
msgid ""
"Failed to allocate PCI devices for instance. Unassigning devices back to "
"pools. This should not happen, since the scheduler should have accurate "
"information, and allocation during claims is controlled via a hold on the "
"compute node semaphore"
msgstr ""

#: nova/pci/pci_utils.py:83 nova/pci/pci_utils.py:99 nova/pci/pci_utils.py:109
#, python-format
msgid "PCI device %s not found"
msgstr ""

#: nova/virt/disk/api.py:388
#, python-format
msgid ""
"Failed to mount container filesystem '%(image)s' on '%(target)s': %(errors)s"
msgstr ""

#: nova/virt/libvirt/driver.py:641
#, python-format
msgid "Nova requires libvirt version %(major)i.%(minor)i.%(micro)i or greater."
msgstr ""

#: nova/virt/libvirt/driver.py:766
#, python-format
msgid "Connection to libvirt failed: %s"
msgstr ""

#: nova/virt/libvirt/driver.py:929
#, python-format
msgid "Error from libvirt during destroy. Code=%(errcode)s Error=%(e)s"
msgstr ""

#: nova/virt/libvirt/driver.py:1007
#, python-format
msgid "Error from libvirt during undefine. Code=%(errcode)s Error=%(e)s"
msgstr ""

#: nova/virt/libvirt/driver.py:1035
#, python-format
msgid "Error from libvirt during unfilter. Code=%(errcode)s Error=%(e)s"
msgstr ""

#: nova/virt/libvirt/driver.py:1438
msgid "attaching network adapter failed."
msgstr ""

#: nova/virt/libvirt/driver.py:1465
msgid "detaching network adapter failed."
msgstr ""

#: nova/virt/libvirt/driver.py:1717
msgid "Failed to send updated snapshot status to volume service."
msgstr ""

#: nova/virt/libvirt/driver.py:1825
msgid ""
"Unable to create quiesced VM snapshot, attempting again with quiescing "
"disabled."
msgstr ""

#: nova/virt/libvirt/driver.py:1831
msgid "Unable to create VM snapshot, failing volume_snapshot operation."
msgstr ""

#: nova/virt/libvirt/driver.py:1880
msgid ""
"Error occurred during volume_snapshot_create, sending error status to Cinder."
msgstr ""

#: nova/virt/libvirt/driver.py:2026
msgid ""
"Error occurred during volume_snapshot_delete, sending error status to Cinder."
msgstr ""

#: nova/virt/libvirt/driver.py:2492 nova/virt/libvirt/driver.py:2497
#, python-format
msgid "Error on '%(path)s' while checking direct I/O: '%(ex)s'"
msgstr ""

#: nova/virt/libvirt/driver.py:2620
#, python-format
msgid "Error injecting data into image %(img_id)s (%(e)s)"
msgstr ""

#: nova/virt/libvirt/driver.py:2788
#, python-format
msgid "Creating config drive failed with error: %s"
msgstr ""

#: nova/virt/libvirt/driver.py:2881
#, python-format
msgid "Attaching PCI devices %(dev)s to %(dom)s failed."
msgstr ""

#: nova/virt/libvirt/driver.py:3680
#, python-format
msgid "Error defining a domain with XML: %s"
msgstr ""

#: nova/virt/libvirt/driver.py:3684
#, python-format
msgid "Error launching a defined domain with XML: %s"
msgstr ""

#: nova/virt/libvirt/driver.py:3689
#, python-format
msgid "Error enabling hairpin mode with XML: %s"
msgstr ""

#: nova/virt/libvirt/driver.py:3703
#, python-format
msgid "Neutron Reported failure on event %(event)s for instance %(uuid)s"
msgstr ""

#: nova/virt/libvirt/driver.py:4012
#, python-format
msgid ""
"Hostname has changed from %(old)s to %(new)s. A restart is required to take "
"effect."
msgstr ""

#: nova/virt/libvirt/driver.py:4691
#, python-format
msgid "Live Migration failure: %s"
msgstr ""

#: nova/virt/libvirt/driver.py:5487
#, python-format
msgid "Failed to cleanup directory %(target)s: %(e)s"
msgstr ""

#: nova/virt/libvirt/imagebackend.py:200
#, python-format
msgid "Unable to preallocate_images=%(imgs)s at path: %(path)s"
msgstr ""

#: nova/virt/libvirt/imagebackend.py:227
#, python-format
msgid ""
"%(base)s virtual size %(base_size)s larger than flavor root disk size "
"%(size)s"
msgstr ""

#: nova/virt/libvirt/imagecache.py:130
#, python-format
msgid "Error reading image info file %(filename)s: %(error)s"
msgstr ""

#: nova/virt/libvirt/imagecache.py:391
#, python-format
msgid "image %(id)s at (%(base_file)s): image verification failed"
msgstr ""

#: nova/virt/libvirt/imagecache.py:448
#, python-format
msgid "Failed to remove %(base_file)s, error was %(error)s"
msgstr ""

#: nova/virt/libvirt/lvm.py:200
#, python-format
msgid "ignoring unrecognized volume_clear='%s' value"
msgstr ""

#: nova/virt/libvirt/rbd.py:62
#, python-format
msgid "error opening rbd image %s"
msgstr ""

#: nova/virt/libvirt/vif.py:485 nova/virt/libvirt/vif.py:509
#: nova/virt/libvirt/vif.py:533
msgid "Failed while plugging vif"
msgstr ""

#: nova/virt/libvirt/vif.py:588 nova/virt/libvirt/vif.py:605
#: nova/virt/libvirt/vif.py:627 nova/virt/libvirt/vif.py:649
#: nova/virt/libvirt/vif.py:674 nova/virt/libvirt/vif.py:696
msgid "Failed while unplugging vif"
msgstr ""

#: nova/virt/libvirt/volume.py:141
#, python-format
msgid "Unknown content in connection_info/access_mode: %s"
msgstr ""

#: nova/virt/libvirt/volume.py:669
#, python-format
msgid "Couldn't unmount the NFS share %s"
msgstr ""

#: nova/virt/libvirt/volume.py:818
#, python-format
msgid "Couldn't unmount the GlusterFS share %s"
msgstr ""

#: nova/virt/vmwareapi/vmops.py:509
#, python-format
msgid ""
"Failed to copy cached image %(source)s to %(dest)s for resize: %(error)s"
msgstr ""

#: nova/virt/vmwareapi/vmops.py:1553
#, python-format
msgid "Attaching network adapter failed. Exception:  %s"
msgstr ""

#: nova/virt/vmwareapi/vmops.py:1593
#, python-format
msgid "Detaching network adapter failed. Exception: %s"
msgstr ""
